[2023-06-22 22:10:01,845] {taskinstance.py:851} INFO - Dependencies all met for <TaskInstance: etl_dag.load_data_from_to_db 2023-06-22T22:09:37.889518+00:00 [queued]>
[2023-06-22 22:10:01,883] {taskinstance.py:851} INFO - Dependencies all met for <TaskInstance: etl_dag.load_data_from_to_db 2023-06-22T22:09:37.889518+00:00 [queued]>
[2023-06-22 22:10:01,884] {taskinstance.py:1042} INFO - 
--------------------------------------------------------------------------------
[2023-06-22 22:10:01,885] {taskinstance.py:1043} INFO - Starting attempt 1 of 1
[2023-06-22 22:10:01,885] {taskinstance.py:1044} INFO - 
--------------------------------------------------------------------------------
[2023-06-22 22:10:01,912] {taskinstance.py:1063} INFO - Executing <Task(_PythonDecoratedOperator): load_data_from_to_db> on 2023-06-22T22:09:37.889518+00:00
[2023-06-22 22:10:01,943] {standard_task_runner.py:52} INFO - Started process 89 to run task
[2023-06-22 22:10:01,956] {standard_task_runner.py:76} INFO - Running: ['airflow', 'tasks', 'run', 'etl_dag', 'load_data_from_to_db', '2023-06-22T22:09:37.889518+00:00', '--job-id', '179', '--pool', 'default_pool', '--raw', '--subdir', 'DAGS_FOLDER/etl_dag.py', '--cfg-path', '/tmp/tmpvbijs2p4', '--error-file', '/tmp/tmponm910ea']
[2023-06-22 22:10:01,958] {standard_task_runner.py:77} INFO - Job 179: Subtask load_data_from_to_db
[2023-06-22 22:10:02,076] {logging_mixin.py:104} INFO - Running <TaskInstance: etl_dag.load_data_from_to_db 2023-06-22T22:09:37.889518+00:00 [running]> on host d6623819d47a
[2023-06-22 22:10:02,164] {taskinstance.py:1257} INFO - Exporting the following env vars:
AIRFLOW_CTX_DAG_OWNER=airflow
AIRFLOW_CTX_DAG_ID=etl_dag
AIRFLOW_CTX_TASK_ID=load_data_from_to_db
AIRFLOW_CTX_EXECUTION_DATE=2023-06-22T22:09:37.889518+00:00
AIRFLOW_CTX_DAG_RUN_ID=manual__2023-06-22T22:09:37.889518+00:00
[2023-06-22 22:10:02,167] {etl_dag.py:40} INFO - loading data from file: transformed/NYC-CHI-2023-08-11.json
[2023-06-22 22:10:02,689] {taskinstance.py:1455} ERROR - An error occurred (NoSuchKey) when calling the GetObject operation: The specified key does not exist.
Traceback (most recent call last):
  File "/home/airflow/.local/lib/python3.6/site-packages/airflow/models/taskinstance.py", line 1112, in _run_raw_task
    self._prepare_and_execute_task_with_callbacks(context, task)
  File "/home/airflow/.local/lib/python3.6/site-packages/airflow/models/taskinstance.py", line 1285, in _prepare_and_execute_task_with_callbacks
    result = self._execute_task(context, task_copy)
  File "/home/airflow/.local/lib/python3.6/site-packages/airflow/models/taskinstance.py", line 1315, in _execute_task
    result = task_copy.execute(context=context)
  File "/home/airflow/.local/lib/python3.6/site-packages/airflow/operators/python.py", line 233, in execute
    return_value = self.python_callable(*self.op_args, **self.op_kwargs)
  File "/opt/airflow/dags/etl_dag.py", line 41, in load_data_from_to_db
    last_records = load_data_from(s3_file)
  File "/opt/airflow/dags/load_to_postgres.py", line 34, in load_data_from
    s3_df = get_s3_data(s3_file)
  File "/opt/airflow/dags/load_to_postgres.py", line 13, in get_s3_data
    response = s3_client.get_object(Bucket=s3_bucket, Key=s3_file_key)
  File "/home/airflow/.local/lib/python3.6/site-packages/botocore/client.py", line 357, in _api_call
    return self._make_api_call(operation_name, kwargs)
  File "/home/airflow/.local/lib/python3.6/site-packages/botocore/client.py", line 676, in _make_api_call
    raise error_class(parsed_response, operation_name)
botocore.errorfactory.NoSuchKey: An error occurred (NoSuchKey) when calling the GetObject operation: The specified key does not exist.
[2023-06-22 22:10:02,707] {taskinstance.py:1503} INFO - Marking task as FAILED. dag_id=etl_dag, task_id=load_data_from_to_db, execution_date=20230622T220937, start_date=20230622T221001, end_date=20230622T221002
[2023-06-22 22:10:02,802] {local_task_job.py:146} INFO - Task exited with return code 1
